#VRML_SIM R2023a utf8
# license: Apache License 2.0
# license url: http://www.apache.org/licenses/LICENSE-2.0
# This is a proto file for Webots for the baxter_xacro
# Extracted from: /tmp/tmphrd7448l.urdf

PROTO baxter [
  field  SFVec3f     translation     0 0 0
  field  SFRotation  rotation        0 0 1 0
  field  SFString    name            "baxter"  # Is `Robot.name`.
  field  SFString    controller      "<extern>"          # Is `Robot.controller`.
  field  MFString    controllerArgs  []              # Is `Robot.controllerArgs`.
  field  SFString    customData      ""              # Is `Robot.customData`.
  field  SFBool      supervisor      FALSE           # Is `Robot.supervisor`.
  field  SFBool      synchronization TRUE            # Is `Robot.synchronization`.
  field  SFBool      selfCollision   FALSE           # Is `Robot.selfCollision`.
]
{
  Robot {
    translation IS translation
    rotation IS rotation
    controller IS controller
    controllerArgs IS controllerArgs
    customData IS customData
    supervisor IS supervisor
    synchronization IS synchronization
    selfCollision IS selfCollision
    children [
      Solid {
        translation 0.110000 0.000000 0.750000
        children [
          Shape {
            appearance DEF red PBRAppearance {
              baseColor 0.590000 0.440000 0.440000
              transparency 0.700000
              roughness 1.000000
              metalness 0
            }
            geometry Sphere {
              radius 0.001
            }
          }
        ]
        name "collision_head_link_1"
        boundingObject Transform {
          translation -0.070000 -0.040000 0.000000
          children [
            Sphere {
              radius 0.22
            }
          ]
        }
        physics Physics {
          density -1
          mass 0.000100
          centerOfMass [ 0.000000 0.000000 0.000000 ]
          inertiaMatrix [
            1.000000e-08 1.000000e-08 1.000000e-08
            0.000000e+00 0.000000e+00 0.000000e+00
          ]
        }
      }
      Solid {
        translation 0.110000 0.000000 0.750000
        children [
          Shape {
            appearance USE red
            geometry Sphere {
              radius 0.001
            }
          }
        ]
        name "collision_head_link_2"
        boundingObject Transform {
          translation -0.070000 0.040000 0.000000
          children [
            Sphere {
              radius 0.22
            }
          ]
        }
        physics Physics {
          density -1
          mass 0.000100
          centerOfMass [ 0.000000 0.000000 0.000000 ]
          inertiaMatrix [
            1.000000e-08 1.000000e-08 1.000000e-08
            0.000000e+00 0.000000e+00 0.000000e+00
          ]
        }
      }
      Solid {
        children [
          DEF base_link_visual CadShape {
            url "baxter/meshes/torso/base_link.DAE"
          }
          Solid {
            translation -0.088970 0.155930 0.389125
            rotation -0.000033 0.707107 0.707107 3.141527
            name "left_torso_itb"
            physics Physics {
              density -1
              mass 0.000100
              centerOfMass [ 0.000000 0.000000 0.000000 ]
              inertiaMatrix [
                1.000000e-08 1.000000e-08 1.000000e-08
                0.000000e+00 0.000000e+00 0.000000e+00
              ]
            }
          }
          Solid {
            translation -0.088970 -0.155930 0.389125
            rotation 1.000000 0.000000 0.000000 1.570796
            name "right_torso_itb"
            physics Physics {
              density -1
              mass 0.000100
              centerOfMass [ 0.000000 0.000000 0.000000 ]
              inertiaMatrix [
                1.000000e-08 1.000000e-08 1.000000e-08
                0.000000e+00 0.000000e+00 0.000000e+00
              ]
            }
          }
          HingeJoint {
            jointParameters HingeJointParameters {
              axis 0.000000 0.000000 1.000000
              anchor 0.060000 0.000000 0.686000
              dampingConstant 0.7
            }
            device [
              RotationalMotor {
                name "head_pan"
                maxVelocity 10000.0
                minPosition -1.3963
                maxPosition 1.3963
                maxTorque 50000.0
              }
              PositionSensor {
                name "head_pan_sensor"
              }
            ]
            endPoint Solid {
              translation 0.060000 0.000000 0.686000
              children [
                Transform {
                  translation 0.000000 0.000000 0.009530
                  children [
                    DEF H0_visual CadShape {
                      url "baxter/meshes/head/H0.DAE"
                    }
                  ]
                }
                Solid {
                  name "dummyhead1"
                  physics Physics {
                    density -1
                    mass 0.000100
                    centerOfMass [ 0.000000 0.000000 0.000000 ]
                    inertiaMatrix [
                      1.000000e-08 1.000000e-08 1.000000e-08
                      0.000000e+00 0.000000e+00 0.000000e+00
                    ]
                  }
                }
                Solid {
                  translation 0.122700 0.000000 0.000000
                  rotation 0.608961 0.608961 0.508265 2.201117
                  children [
                    Transform {
                      translation 0.000000 -0.009530 -0.034700
                      rotation 0.000000 -1.000000 0.000000 1.570796
                      children [
                        DEF H1_visual CadShape {
                          url "baxter/meshes/head/H1.DAE"
                        }
                      ]
                    }
                    Solid {
                      translation 0.000000 -0.016000 0.000000
                      children [
                        Transform {
                          rotation 1.000000 0.000000 0.000000 0.261799
                          children [
                            Shape {
                              appearance DEF black PBRAppearance {
                                baseColor 0.000000 0.000000 0.000000
                                roughness 1.000000
                                metalness 0
                              }
                              geometry Box {
                                 size 0.218000 0.160000 0.001000
                              }
                            }
                          ]
                        }
                      ]
                      name "display"
                      physics Physics {
                        density -1
                        mass 0.000100
                        centerOfMass [ 0.000000 0.000000 0.000000 ]
                        inertiaMatrix [
                          1.000000e-08 1.000000e-08 1.000000e-08
                          0.000000e+00 0.000000e+00 0.000000e+00
                        ]
                      }
                    }
                  ]
                  name "screen"
                  boundingObject Sphere {
                    radius 0.001
                  }
                  physics Physics {
                    density -1
                    mass 0.440171
                    centerOfMass [ 0.000000 0.000000 0.000000 ]
                    inertiaMatrix [
                      4.006000e-03 2.800000e-03 1.509000e-03
                      2.300000e-04 2.000000e-06 2.900000e-05
                    ]
                  }
                }
                Solid {
                  translation 0.128390 0.000000 0.063680
                  rotation 0.608961 0.608961 0.508265 2.201117
                  name "head_camera"
                  physics Physics {
                    density -1
                    mass 0.000100
                    centerOfMass [ 0.000000 0.000000 0.000000 ]
                    inertiaMatrix [
                      1.000000e-08 1.000000e-08 1.000000e-08
                      0.000000e+00 0.000000e+00 0.000000e+00
                    ]
                  }
                }
              ]
              name "head"
              boundingObject Sphere {
                radius 0.001
              }
              physics Physics {
                density -1
                mass 0.547767
                centerOfMass [ 0.000000 0.000000 0.000000 ]
                inertiaMatrix [
                  4.641000e-03 3.295000e-03 3.415000e-03
                  1.590000e-04 2.420000e-04 -1.324000e-03
                ]
              }
            }
          }
          Solid {
            translation 0.094700 0.000000 0.817000
            children [
              Transform {
                translation -0.034700 0.000000 0.009530
                children [
                  Shape {
                    appearance DEF darkgray PBRAppearance {
                      baseColor 0.200000 0.200000 0.200000
                      roughness 1.000000
                      metalness 0
                    }
                    geometry Cylinder {
                      radius 0.085
                      height 0.01
                    }
                  }
                ]
              }
            ]
            name "sonar_ring"
            boundingObject Sphere {
              radius 0.001
            }
            physics Physics {
              density -1
              mass 0.000100
              centerOfMass [ 0.000000 0.000000 0.000000 ]
              inertiaMatrix [
                1.000000e-08 1.000000e-08 1.000000e-08
                0.000000e+00 0.000000e+00 0.000000e+00
              ]
            }
          }
          Solid {
            translation 0.024645 -0.219645 0.118588
            rotation 0.000000 0.000000 -1.000000 0.785400
            children [
              HingeJoint {
                jointParameters HingeJointParameters {
                  axis 0.000000 0.000000 1.000000
                  anchor 0.055695 0.000000 0.011038
                  dampingConstant 0.7
                }
                device [
                  RotationalMotor {
                    name "right_s0"
                    maxVelocity 1.5
                    minPosition -1.70167993878
                    maxPosition 1.70167993878
                    maxTorque 50.0
                  }
                  PositionSensor {
                    name "right_s0_sensor"
                  }
                ]
                endPoint Solid {
                  translation 0.055695 0.000000 0.011038
                  children [
                    DEF S0_visual CadShape {
                      url "baxter/meshes/upper_shoulder/S0.DAE"
                    }
                    HingeJoint {
                      jointParameters HingeJointParameters {
                        axis 0.000000 1.000000 0.000000
                        anchor 0.069000 0.000000 0.270350
                        dampingConstant 0.7
                      }
                      device [
                        RotationalMotor {
                          name "right_s1"
                          maxVelocity 1.5
                          minPosition -2.147
                          maxPosition 1.047
                          maxTorque 50.0
                        }
                        PositionSensor {
                          name "right_s1_sensor"
                        }
                      ]
                      endPoint Solid {
                        translation 0.069000 0.000000 0.270350
                        rotation -1.000000 0.000000 0.000000 1.570796
                        children [
                          DEF S1_visual CadShape {
                            url "baxter/meshes/lower_shoulder/S1.DAE"
                          }
                          HingeJoint {
                            jointParameters HingeJointParameters {
                              axis 1.000000 -0.000000 0.000000
                              anchor 0.102000 0.000000 0.000000
                              dampingConstant 0.7
                            }
                            device [
                              RotationalMotor {
                                name "right_e0"
                                maxVelocity 1.5
                                minPosition -3.05417993878
                                maxPosition 3.05417993878
                                maxTorque 50.0
                              }
                              PositionSensor {
                                name "right_e0_sensor"
                              }
                            ]
                            endPoint Solid {
                              translation 0.102000 0.000000 0.000000
                              rotation 0.577350 0.577350 0.577350 2.094395
                              children [
                                DEF E0_visual CadShape {
                                  url "baxter/meshes/upper_elbow/E0.DAE"
                                }
                                HingeJoint {
                                  jointParameters HingeJointParameters {
                                    axis -0.000000 1.000000 -0.000000
                                    anchor 0.069000 0.000000 0.262420
                                    dampingConstant 0.7
                                  }
                                  device [
                                    RotationalMotor {
                                      name "right_e1"
                                      maxVelocity 1.5
                                      minPosition -0.05
                                      maxPosition 2.618
                                      maxTorque 50.0
                                    }
                                    PositionSensor {
                                      name "right_e1_sensor"
                                    }
                                  ]
                                  endPoint Solid {
                                    translation 0.069000 0.000000 0.262420
                                    rotation -0.577350 -0.577350 -0.577350 2.094395
                                    children [
                                      DEF E1_visual CadShape {
                                        url "baxter/meshes/lower_elbow/E1.DAE"
                                      }
                                      HingeJoint {
                                        jointParameters HingeJointParameters {
                                          axis 1.000000 -0.000000 0.000000
                                          anchor 0.103590 0.000000 0.000000
                                          dampingConstant 0.7
                                        }
                                        device [
                                          RotationalMotor {
                                            name "right_w0"
                                            maxVelocity 4.0
                                            minPosition -3.059
                                            maxPosition 3.059
                                            maxTorque 15.0
                                          }
                                          PositionSensor {
                                            name "right_w0_sensor"
                                          }
                                        ]
                                        endPoint Solid {
                                          translation 0.103590 0.000000 0.000000
                                          rotation 0.577350 0.577350 0.577350 2.094395
                                          children [
                                            DEF W0_visual CadShape {
                                              url "baxter/meshes/upper_forearm/W0.DAE"
                                            }
                                            Solid {
                                              translation -0.056500 0.000000 0.120000
                                              rotation -0.577350 -0.577350 0.577350 2.094395
                                              name "right_arm_itb"
                                              physics Physics {
                                                density -1
                                                mass 0.000100
                                                centerOfMass [ 0.000000 0.000000 0.000000 ]
                                                inertiaMatrix [
                                                  1.000000e-08 1.000000e-08 1.000000e-08
                                                  0.000000e+00 0.000000e+00 0.000000e+00
                                                ]
                                              }
                                            }
                                            HingeJoint {
                                              jointParameters HingeJointParameters {
                                                axis -0.000000 1.000000 -0.000000
                                                anchor 0.010000 0.000000 0.270700
                                                dampingConstant 0.7
                                              }
                                              device [
                                                RotationalMotor {
                                                  name "right_w1"
                                                  maxVelocity 4.0
                                                  minPosition -1.57079632679
                                                  maxPosition 2.094
                                                  maxTorque 15.0
                                                }
                                                PositionSensor {
                                                  name "right_w1_sensor"
                                                }
                                              ]
                                              endPoint Solid {
                                                translation 0.010000 0.000000 0.270700
                                                rotation -0.577350 -0.577350 -0.577350 2.094395
                                                children [
                                                  DEF W1_visual CadShape {
                                                    url "baxter/meshes/lower_forearm/W1.DAE"
                                                  }
                                                  HingeJoint {
                                                    jointParameters HingeJointParameters {
                                                      axis 1.000000 -0.000000 0.000000
                                                      anchor 0.115975 0.000000 0.000000
                                                      dampingConstant 0.7
                                                    }
                                                    device [
                                                      RotationalMotor {
                                                        name "right_w2"
                                                        maxVelocity 4.0
                                                        minPosition -3.059
                                                        maxPosition 3.059
                                                        maxTorque 15.0
                                                      }
                                                      PositionSensor {
                                                        name "right_w2_sensor"
                                                      }
                                                    ]
                                                    endPoint Solid {
                                                      translation 0.115975 0.000000 0.000000
                                                      rotation 0.577350 0.577350 0.577350 2.094395
                                                      children [
                                                        DEF W2_visual CadShape {
                                                          url "baxter/meshes/wrist/W2.DAE"
                                                        }
                                                        Solid {
                                                          translation 0.000000 0.000000 0.113550
                                                          children [
                                                            Solid {
                                                              translation 0.038250 0.012000 0.015355
                                                              rotation 0.000000 0.000000 -1.000000 1.570796
                                                              children [
                                                                Shape {
                                                                  appearance DEF blue PBRAppearance {
                                                                    baseColor 0.100000 0.100000 0.900000
                                                                    transparency 0.200000
                                                                    roughness 1.000000
                                                                    metalness 0
                                                                  }
                                                                  geometry Cylinder {
                                                                    radius 0.02
                                                                    height 0.01
                                                                  }
                                                                }
                                                              ]
                                                              name "right_hand_camera"
                                                              physics Physics {
                                                                density -1
                                                                mass 0.000100
                                                                centerOfMass [ 0.000000 0.000000 0.000000 ]
                                                                inertiaMatrix [
                                                                  1.000000e-08 1.000000e-08 1.000000e-08
                                                                  0.000000e+00 0.000000e+00 0.000000e+00
                                                                ]
                                                              }
                                                            }
                                                            Solid {
                                                              translation 0.038250 0.012000 0.015355
                                                              children [
                                                                Solid {
                                                                  rotation 0.000000 -1.000000 0.000000 1.570796
                                                                  children [
                                                                    Solid {
                                                                      translation 0 0 0
                                                                      rotation 0.577350 -0.577350 0.577350 2.094395
                                                                      children [
                                                                        Camera {
                                                                          name "right_camera"
                                                                          fieldOfView 1.047000
                                                                          width 640
                                                                          height 400
                                                                        }
                                                                      ]
                                                                    }
                                                                  ]
                                                                  name "right_hand_camera_gz"
                                                                }
                                                              ]
                                                              name "right_hand_camera_axis"
                                                              physics Physics {
                                                                density -1
                                                                mass 0.000100
                                                                centerOfMass [ 0.000000 0.000000 0.000000 ]
                                                                inertiaMatrix [
                                                                  1.000000e-08 1.000000e-08 1.000000e-08
                                                                  0.000000e+00 0.000000e+00 0.000000e+00
                                                                ]
                                                              }
                                                            }
                                                            Solid {
                                                              translation 0.032000 -0.020245 0.028800
                                                              rotation -0.577350 -0.577350 -0.577350 2.094395
                                                              children [
                                                                Shape {
                                                                  appearance USE blue
                                                                  geometry Box {
                                                                     size 0.005000 0.020000 0.005000
                                                                  }
                                                                }
                                                              ]
                                                              name "right_hand_range"
                                                              physics Physics {
                                                                density -1
                                                                mass 0.000100
                                                                centerOfMass [ 0.000000 0.000000 0.000000 ]
                                                                inertiaMatrix [
                                                                  1.000000e-08 1.000000e-08 1.000000e-08
                                                                  0.000000e+00 0.000000e+00 0.000000e+00
                                                                ]
                                                              }
                                                            }
                                                            Solid {
                                                              translation 0.001980 0.000133 -0.014600
                                                              children [
                                                                Shape {
                                                                  appearance USE black
                                                                  geometry Box {
                                                                     size 0.010000 0.010000 0.010000
                                                                  }
                                                                }
                                                              ]
                                                              name "right_hand_accelerometer"
                                                              physics Physics {
                                                                density -1
                                                                mass 0.000100
                                                                centerOfMass [ 0.000000 0.000000 0.000000 ]
                                                                inertiaMatrix [
                                                                  1.000000e-08 1.000000e-08 1.000000e-08
                                                                  0.000000e+00 0.000000e+00 0.000000e+00
                                                                ]
                                                              }
                                                            }
                                                            Solid {
                                                              translation 0.000000 0.000000 0.025000
                                                              children [
                                                                Solid {
                                                                  rotation -0.000000 0.707107 0.707107 3.141593
                                                                  children [
                                                                    DEF electric_gripper_base_visual CadShape {
                                                                      url "baxter/meshes/electric_gripper/electric_gripper_base.DAE"
                                                                    }
                                                                  ]
                                                                }
                                                                Solid {
                                                                  translation 0.000000 0.000000 0.132700
                                                                  name "right_gripper"
                                                                  physics Physics {
                                                                    density -1
                                                                    mass 0.000100
                                                                  }
                                                                }
                                                                SliderJoint {
                                                                  jointParameters JointParameters {
                                                                    axis 0.000000 1.000000 0.000000
                                                                    dampingConstant 0.7
                                                                  }
                                                                  device [
                                                                    LinearMotor {
                                                                      name "r_gripper_l_finger_joint"
                                                                      maxVelocity 5.0
                                                                      maxPosition 0.020833
                                                                      maxForce 20.0
                                                                    }
                                                                    PositionSensor {
                                                                      name "r_gripper_l_finger_joint_sensor"
                                                                    }
                                                                  ]
                                                                  endPoint Solid {
                                                                    translation 0.000000 -0.001500 0.020000
                                                                    children [
                                                                      Solid {
                                                                        rotation 0.000000 0.000000 -1.000000 3.141593
                                                                        children [
                                                                          DEF extended_narrow_visual CadShape {
                                                                            url "baxter/meshes/electric_gripper/fingers/extended_narrow.DAE"
                                                                          }
                                                                        ]
                                                                      }
                                                                      Solid {
                                                                        translation 0.000000 0.017250 0.112700
                                                                        children [
                                                                          Solid {
                                                                            rotation 0.000000 0.000000 1.000000 3.141593
                                                                            children [
                                                                              DEF half_round_tip_visual CadShape {
                                                                                url "baxter/meshes/electric_gripper/fingers/half_round_tip.DAE"
                                                                              }
                                                                            ]
                                                                          }
                                                                        ]
                                                                        name "r_gripper_l_finger_tip"
                                                                        boundingObject Transform {
                                                                          translation 0.000000 -0.004500 -0.015000
                                                                          rotation 0.000000 0.000000 1.000000 3.141593
                                                                          children [
                                                                            Cylinder {
                                                                              radius 0.008
                                                                              height 0.037
                                                                            }
                                                                          ]
                                                                        }
                                                                        physics Physics {
                                                                          density -1
                                                                          mass 0.010000
                                                                          centerOfMass [ 0.000000 0.000000 0.000000 ]
                                                                          inertiaMatrix [
                                                                            1.000000e-02 1.000000e-02 1.000000e-02
                                                                            0.000000e+00 0.000000e+00 0.000000e+00
                                                                          ]
                                                                        }
                                                                      }
                                                                    ]
                                                                    name "r_gripper_l_finger"
                                                                    boundingObject Group {
                                                                      children [
                                                                        Transform {
                                                                          translation 0.000000 0.017250 0.061500
                                                                          rotation 0.000000 0.000000 -1.000000 3.141593
                                                                          children [
                                                                            Box {
                                                                               size 0.010000 0.013500 0.112700
                                                                            }
                                                                          ]
                                                                        }
                                                                        Transform {
                                                                          translation -0.005000 -0.003000 0.008300
                                                                          rotation 0.000000 0.000000 -1.000000 3.141593
                                                                          children [
                                                                            Box {
                                                                               size 0.010000 0.050000 0.017000
                                                                            }
                                                                          ]
                                                                        }
                                                                      ]
                                                                    }
                                                                    physics Physics {
                                                                      density -1
                                                                      mass 0.020000
                                                                      centerOfMass [ 0.000000 0.000000 0.000000 ]
                                                                      inertiaMatrix [
                                                                        1.000000e-02 1.000000e-02 1.000000e-02
                                                                        0.000000e+00 0.000000e+00 0.000000e+00
                                                                      ]
                                                                    }
                                                                  }
                                                                }
                                                                SliderJoint {
                                                                  jointParameters JointParameters {
                                                                    axis 0.000000 1.000000 0.000000
                                                                    dampingConstant 0.7
                                                                  }
                                                                  device [
                                                                    LinearMotor {
                                                                      name "r_gripper_r_finger_joint"
                                                                      maxVelocity 5.0
                                                                      minPosition -0.020833
                                                                      maxForce 20.0
                                                                    }
                                                                    PositionSensor {
                                                                      name "r_gripper_r_finger_joint_sensor"
                                                                    }
                                                                  ]
                                                                  endPoint Solid {
                                                                    translation 0.000000 0.001500 0.020000
                                                                    children [
                                                                      USE extended_narrow_visual
                                                                      Solid {
                                                                        translation 0.000000 -0.017250 0.112700
                                                                        children [
                                                                          USE half_round_tip_visual
                                                                        ]
                                                                        name "r_gripper_r_finger_tip"
                                                                        boundingObject Transform {
                                                                          translation 0.000000 0.004500 -0.015000
                                                                          children [
                                                                          Shape {
                                                                           geometry Cylinder {
                                                                              radius 0.008
                                                                              height 0.037
                                                                            }
                                                                            }
                                                                          ]
                                                                        }
                                                                        physics Physics {
                                                                          density -1
                                                                          mass 0.010000
                                                                          centerOfMass [ 0.000000 0.000000 0.000000 ]
                                                                          inertiaMatrix [
                                                                            1.000000e-02 1.000000e-02 1.000000e-02
                                                                            0.000000e+00 0.000000e+00 0.000000e+00
                                                                          ]
                                                                        }
                                                                      }
                                                                    ]
                                                                    name "r_gripper_r_finger"
                                                                    boundingObject Group {
                                                                      children [
                                                                        Transform {
                                                                          translation 0.000000 -0.017250 0.061500
                                                                          children [
                                                                            Box {
                                                                               size 0.010000 0.013500 0.112700
                                                                            }
                                                                          ]
                                                                        }
                                                                        Transform {
                                                                          translation 0.005000 0.003000 0.008300
                                                                          children [
                                                                            Box {
                                                                               size 0.010000 0.050000 0.017000
                                                                            }
                                                                          ]
                                                                        }
                                                                      ]
                                                                    }
                                                                    physics Physics {
                                                                      density -1
                                                                      mass 0.020000
                                                                      centerOfMass [ 0.000000 0.000000 0.000000 ]
                                                                      inertiaMatrix [
                                                                        1.000000e-02 1.000000e-02 1.000000e-02
                                                                        0.000000e+00 0.000000e+00 0.000000e+00
                                                                      ]
                                                                    }
                                                                  }
                                                                }
                                                              ]
                                                              name "right_gripper_base"
                                                              boundingObject Transform {
                                                                rotation -0.000000 0.707107 0.707107 3.141593
                                                                children [
                                                                  Cylinder {
                                                                    radius 0.029
                                                                    height 0.1
                                                                  }
                                                                ]
                                                              }
                                                              physics Physics {
                                                                density -1
                                                                mass 0.300000
                                                                centerOfMass [ 0.000000 0.000000 0.000000 ]
                                                                inertiaMatrix [
                                                                  2.000000e-08 2.000000e-08 3.000000e-08
                                                                  0.000000e+00 2.536327e-25 2.220446e-24
                                                                ]
                                                              }
                                                            }
                                                          ]
                                                          name "right_hand"
                                                          boundingObject Transform {
                                                            translation 0.000000 0.000000 -0.023200
                                                            children [
                                                              Cylinder {
                                                                radius 0.04
                                                                height 0.0464
                                                              }
                                                            ]
                                                          }
                                                          physics Physics {
                                                            density -1
                                                            mass 0.191250
                                                            centerOfMass [ 0.010930 0.000420 -0.015320 ]
                                                            inertiaMatrix [
                                                              1.758800e-04 2.116638e-04 2.374540e-04
                                                              1.470730e-06 2.436330e-05 1.726890e-06
                                                            ]
                                                          }
                                                        }
                                                      ]
                                                      name "right_wrist"
                                                      boundingObject Cylinder {
                                                        radius 0.06
                                                        height 0.165
                                                      }
                                                      physics Physics {
                                                        density -1
                                                        mass 0.350930
                                                        centerOfMass [ 0.001980 0.001250 0.018550 ]
                                                        inertiaMatrix [
                                                          2.528916e-04 2.688601e-04 3.074118e-04
                                                          5.753110e-06 -1.593450e-06 -5.198180e-06
                                                        ]
                                                      }
                                                    }
                                                  }
                                                ]
                                                name "right_lower_forearm"
                                                boundingObject Cylinder {
                                                  radius 0.06
                                                  height 0.1
                                                }
                                                physics Physics {
                                                  density -1
                                                  mass 1.609790
                                                  centerOfMass [ 0.060410 0.006970 0.006000 ]
                                                  inertiaMatrix [
                                                    3.876072e-03 7.005379e-03 5.527552e-03
                                                    -4.438478e-04 -2.111504e-04 1.534807e-04
                                                  ]
                                                }
                                              }
                                            }
                                          ]
                                          name "right_upper_forearm"
                                          boundingObject Transform {
                                            translation 0.000000 0.000000 -0.044000
                                            children [
                                              Cylinder {
                                                radius 0.06
                                                height 0.088
                                              }
                                            ]
                                          }
                                          physics Physics {
                                            density -1
                                            mass 2.246650
                                            centerOfMass [ -0.001680 0.004600 0.139520 ]
                                            inertiaMatrix [
                                              1.667743e-02 1.675457e-02 3.746312e-03
                                              1.840371e-04 1.865763e-04 -6.473235e-04
                                            ]
                                          }
                                        }
                                      }
                                      Solid {
                                        translation 0.088000 0.000000 0.000000
                                        rotation 0.577350 0.577350 0.577350 2.094395
                                        name "right_upper_forearm_visual"
                                        boundingObject Transform {
                                          translation 0.000000 0.000000 0.136000
                                          children [
                                            Cylinder {
                                              radius 0.06
                                              height 0.272
                                            }
                                          ]
                                        }
                                        physics Physics {
                                          density -1
                                          mass 0.000100
                                          centerOfMass [ 0.000000 0.000000 0.000000 ]
                                          inertiaMatrix [
                                            1.000000e-08 1.000000e-08 1.000000e-08
                                            0.000000e+00 0.000000e+00 0.000000e+00
                                          ]
                                        }
                                      }
                                    ]
                                    name "right_lower_elbow"
                                    boundingObject Cylinder {
                                      radius 0.06
                                      height 0.1
                                    }
                                    physics Physics {
                                      density -1
                                      mass 2.072060
                                      centerOfMass [ 0.026110 0.001590 -0.011170 ]
                                      inertiaMatrix [
                                        7.115827e-03 1.318228e-02 9.268521e-03
                                        3.603617e-04 7.459496e-04 -1.966342e-04
                                      ]
                                    }
                                  }
                                }
                              ]
                              name "right_upper_elbow"
                              boundingObject Transform {
                                translation 0.000000 0.000000 -0.053500
                                children [
                                  Cylinder {
                                    radius 0.06
                                    height 0.107
                                  }
                                ]
                              }
                              physics Physics {
                                density -1
                                mass 4.312720
                                centerOfMass [ -0.002760 0.001320 0.180860 ]
                                inertiaMatrix [
                                  2.661734e-02 2.844355e-02 1.248008e-02
                                  2.927063e-04 3.921899e-03 1.083893e-03
                                ]
                              }
                            }
                          }
                          Solid {
                            translation 0.107000 0.000000 0.000000
                            rotation 0.577350 0.577350 0.577350 2.094395
                            name "right_upper_elbow_visual"
                            boundingObject Transform {
                              translation 0.000000 0.000000 0.136500
                              children [
                                Cylinder {
                                  radius 0.06
                                  height 0.273
                                }
                              ]
                            }
                            physics Physics {
                              density -1
                              mass 0.000100
                              centerOfMass [ 0.000000 0.000000 0.000000 ]
                              inertiaMatrix [
                                1.000000e-08 1.000000e-08 1.000000e-08
                                0.000000e+00 0.000000e+00 0.000000e+00
                              ]
                            }
                          }
                        ]
                        name "right_lower_shoulder"
                        boundingObject Cylinder {
                          radius 0.06
                          height 0.12
                        }
                        physics Physics {
                          density -1
                          mass 3.226980
                          centerOfMass [ 0.068450 0.002690 -0.005290 ]
                          inertiaMatrix [
                            1.175209e-02 2.788598e-02 2.078749e-02
                            -3.009640e-04 2.076758e-03 -1.882199e-04
                          ]
                        }
                      }
                    }
                  ]
                  name "right_upper_shoulder"
                  boundingObject Transform {
                    translation 0.000000 0.000000 0.136100
                    children [
                      Cylinder {
                        radius 0.06
                        height 0.2722
                      }
                    ]
                  }
                  physics Physics {
                    density -1
                    mass 5.700440
                    centerOfMass [ 0.017830 0.000860 0.191270 ]
                    inertiaMatrix [
                      4.709102e-02 3.766976e-02 3.595988e-02
                      1.278756e-04 6.148700e-03 7.808690e-04
                    ]
                  }
                }
              }
            ]
            name "right_arm_mount"
            physics Physics {
              density -1
              mass 0.000100
              centerOfMass [ 0.000000 0.000000 0.000000 ]
              inertiaMatrix [
                1.000000e-08 1.000000e-08 1.000000e-08
                0.000000e+00 0.000000e+00 0.000000e+00
              ]
            }
          }
          Solid {
            translation 0.024645 0.219645 0.118588
            rotation 0.000000 0.000000 1.000000 0.785400
            children [
              HingeJoint {
                jointParameters HingeJointParameters {
                  axis 0.000000 0.000000 1.000000
                  anchor 0.055695 0.000000 0.011038
                  dampingConstant 0.7
                }
                device [
                  RotationalMotor {
                    name "left_s0"
                    maxVelocity 1.5
                    minPosition -1.70167993878
                    maxPosition 1.70167993878
                    maxTorque 50.0
                  }
                  PositionSensor {
                    name "left_s0_sensor"
                  }
                ]
                endPoint Solid {
                  translation 0.055695 0.000000 0.011038
                  children [
                    USE S0_visual
                    HingeJoint {
                      jointParameters HingeJointParameters {
                        axis 0.000000 1.000000 0.000000
                        anchor 0.069000 0.000000 0.270350
                        dampingConstant 0.7
                      }
                      device [
                        RotationalMotor {
                          name "left_s1"
                          maxVelocity 1.5
                          minPosition -2.147
                          maxPosition 1.047
                          maxTorque 50.0
                        }
                        PositionSensor {
                          name "left_s1_sensor"
                        }
                      ]
                      endPoint Solid {
                        translation 0.069000 0.000000 0.270350
                        rotation -1.000000 0.000000 0.000000 1.570796
                        children [
                          USE S1_visual
                          HingeJoint {
                            jointParameters HingeJointParameters {
                              axis 1.000000 -0.000000 0.000000
                              anchor 0.102000 0.000000 0.000000
                              dampingConstant 0.7
                            }
                            device [
                              RotationalMotor {
                                name "left_e0"
                                maxVelocity 1.5
                                minPosition -3.05417993878
                                maxPosition 3.05417993878
                                maxTorque 50.0
                              }
                              PositionSensor {
                                name "left_e0_sensor"
                              }
                            ]
                            endPoint Solid {
                              translation 0.102000 0.000000 0.000000
                              rotation 0.577350 0.577350 0.577350 2.094395
                              children [
                                USE E0_visual
                                HingeJoint {
                                  jointParameters HingeJointParameters {
                                    axis -0.000000 1.000000 -0.000000
                                    anchor 0.069000 0.000000 0.262420
                                    dampingConstant 0.7
                                  }
                                  device [
                                    RotationalMotor {
                                      name "left_e1"
                                      maxVelocity 1.5
                                      minPosition -0.05
                                      maxPosition 2.618
                                      maxTorque 50.0
                                    }
                                    PositionSensor {
                                      name "left_e1_sensor"
                                    }
                                  ]
                                  endPoint Solid {
                                    translation 0.069000 0.000000 0.262420
                                    rotation -0.577350 -0.577350 -0.577350 2.094395
                                    children [
                                      USE E1_visual
                                      HingeJoint {
                                        jointParameters HingeJointParameters {
                                          axis 1.000000 -0.000000 0.000000
                                          anchor 0.103590 0.000000 0.000000
                                          dampingConstant 0.7
                                        }
                                        device [
                                          RotationalMotor {
                                            name "left_w0"
                                            maxVelocity 4.0
                                            minPosition -3.059
                                            maxPosition 3.059
                                            maxTorque 15.0
                                          }
                                          PositionSensor {
                                            name "left_w0_sensor"
                                          }
                                        ]
                                        endPoint Solid {
                                          translation 0.103590 0.000000 0.000000
                                          rotation 0.577350 0.577350 0.577350 2.094395
                                          children [
                                            USE W0_visual
                                            Solid {
                                              translation -0.056500 0.000000 0.120000
                                              rotation -0.577350 -0.577350 0.577350 2.094395
                                              name "left_arm_itb"
                                              physics Physics {
                                                density -1
                                                mass 0.000100
                                                centerOfMass [ 0.000000 0.000000 0.000000 ]
                                                inertiaMatrix [
                                                  1.000000e-08 1.000000e-08 1.000000e-08
                                                  0.000000e+00 0.000000e+00 0.000000e+00
                                                ]
                                              }
                                            }
                                            HingeJoint {
                                              jointParameters HingeJointParameters {
                                                axis -0.000000 1.000000 -0.000000
                                                anchor 0.010000 0.000000 0.270700
                                                dampingConstant 0.7
                                              }
                                              device [
                                                RotationalMotor {
                                                  name "left_w1"
                                                  maxVelocity 4.0
                                                  minPosition -1.57079632679
                                                  maxPosition 2.094
                                                  maxTorque 15.0
                                                }
                                                PositionSensor {
                                                  name "left_w1_sensor"
                                                }
                                              ]
                                              endPoint Solid {
                                                translation 0.010000 0.000000 0.270700
                                                rotation -0.577350 -0.577350 -0.577350 2.094395
                                                children [
                                                  USE W1_visual
                                                  HingeJoint {
                                                    jointParameters HingeJointParameters {
                                                      axis 1.000000 -0.000000 0.000000
                                                      anchor 0.115975 0.000000 0.000000
                                                      dampingConstant 0.7
                                                    }
                                                    device [
                                                      RotationalMotor {
                                                        name "left_w2"
                                                        maxVelocity 4.0
                                                        minPosition -3.059
                                                        maxPosition 3.059
                                                        maxTorque 15.0
                                                      }
                                                      PositionSensor {
                                                        name "left_w2_sensor"
                                                      }
                                                    ]
                                                    endPoint Solid {
                                                      translation 0.115975 0.000000 0.000000
                                                      rotation 0.577350 0.577350 0.577350 2.094395
                                                      children [
                                                        USE W2_visual
                                                        Solid {
                                                          translation 0.000000 0.000000 0.113550
                                                          children [
                                                            Solid {
                                                              translation 0.038250 0.012000 0.015355
                                                              rotation 0.000000 0.000000 -1.000000 1.570796
                                                              children [
                                                                Shape {
                                                                  appearance USE blue
                                                                  geometry Cylinder {
                                                                    radius 0.02
                                                                    height 0.01
                                                                  }
                                                                }
                                                              ]
                                                              name "left_hand_camera"
                                                              physics Physics {
                                                                density -1
                                                                mass 0.000100
                                                                centerOfMass [ 0.000000 0.000000 0.000000 ]
                                                                inertiaMatrix [
                                                                  1.000000e-08 1.000000e-08 1.000000e-08
                                                                  0.000000e+00 0.000000e+00 0.000000e+00
                                                                ]
                                                              }
                                                            }
                                                            Solid {
                                                              translation 0.038250 0.012000 0.015355
                                                              children [
                                                                Solid {
                                                                  rotation 0.000000 -1.000000 0.000000 1.570796
                                                                  children [
                                                                    Solid {
                                                                      translation 0 0 0
                                                                      rotation 0.577350 -0.577350 0.577350 2.094395
                                                                      children [
                                                                        Camera {
                                                                          name "left_camera"
                                                                          fieldOfView 1.047000
                                                                          width 640
                                                                          height 400
                                                                        }
                                                                      ]
                                                                    }
                                                                  ]
                                                                  name "left_hand_camera_gz"
                                                                }
                                                              ]
                                                              name "left_hand_camera_axis"
                                                              physics Physics {
                                                                density -1
                                                                mass 0.000100
                                                                centerOfMass [ 0.000000 0.000000 0.000000 ]
                                                                inertiaMatrix [
                                                                  1.000000e-08 1.000000e-08 1.000000e-08
                                                                  0.000000e+00 0.000000e+00 0.000000e+00
                                                                ]
                                                              }
                                                            }
                                                            Solid {
                                                              translation 0.032000 -0.020245 0.028800
                                                              rotation -0.577350 -0.577350 -0.577350 2.094395
                                                              children [
                                                                Shape {
                                                                  appearance USE blue
                                                                  geometry Box {
                                                                     size 0.005000 0.020000 0.005000
                                                                  }
                                                                }
                                                              ]
                                                              name "left_hand_range"
                                                              physics Physics {
                                                                density -1
                                                                mass 0.000100
                                                                centerOfMass [ 0.000000 0.000000 0.000000 ]
                                                                inertiaMatrix [
                                                                  1.000000e-08 1.000000e-08 1.000000e-08
                                                                  0.000000e+00 0.000000e+00 0.000000e+00
                                                                ]
                                                              }
                                                            }
                                                            Solid {
                                                              translation 0.001980 0.000133 -0.014600
                                                              children [
                                                                Shape {
                                                                  appearance USE black
                                                                  geometry Box {
                                                                     size 0.010000 0.010000 0.010000
                                                                  }
                                                                }
                                                              ]
                                                              name "left_hand_accelerometer"
                                                              physics Physics {
                                                                density -1
                                                                mass 0.000100
                                                                centerOfMass [ 0.000000 0.000000 0.000000 ]
                                                                inertiaMatrix [
                                                                  1.000000e-08 1.000000e-08 1.000000e-08
                                                                  0.000000e+00 0.000000e+00 0.000000e+00
                                                                ]
                                                              }
                                                            }
                                                            Solid {
                                                              translation 0.000000 0.000000 0.025000
                                                              children [
                                                                Solid {
                                                                  rotation -0.000000 0.707107 0.707107 3.141593
                                                                  children [
                                                                    USE electric_gripper_base_visual
                                                                  ]
                                                                }
                                                                Solid {
                                                                  translation 0.000000 0.000000 0.132700
                                                                  name "left_gripper"
                                                                  physics Physics {
                                                                    density -1
                                                                    mass 0.000100
                                                                  }
                                                                }
                                                                SliderJoint {
                                                                  jointParameters JointParameters {
                                                                    axis 0.000000 1.000000 0.000000
                                                                    dampingConstant 0.7
                                                                  }
                                                                  device [
                                                                    LinearMotor {
                                                                      name "l_gripper_l_finger_joint"
                                                                      maxVelocity 5.0
                                                                      maxPosition 0.020833
                                                                      maxForce 20.0
                                                                    }
                                                                    PositionSensor {
                                                                      name "l_gripper_l_finger_joint_sensor"
                                                                    }
                                                                  ]
                                                                  endPoint Solid {
                                                                    translation 0.000000 -0.001500 0.020000
                                                                    children [
                                                                      Solid {
                                                                        rotation 0.000000 0.000000 -1.000000 3.141593
                                                                        children [
                                                                          USE extended_narrow_visual
                                                                        ]
                                                                      }
                                                                      Solid {
                                                                        translation 0.000000 0.017250 0.112700
                                                                        children [
                                                                          Solid {
                                                                            rotation 0.000000 0.000000 1.000000 3.141593
                                                                            children [
                                                                              DEF paddle_tip_visual CadShape {
                                                                                url "baxter/meshes/electric_gripper/fingers/paddle_tip.DAE"
                                                                              }
                                                                            ]
                                                                          }
                                                                        ]
                                                                        name "l_gripper_l_finger_tip"
                                                                        boundingObject Transform {
                                                                          translation 0.000000 -0.004500 -0.015000
                                                                          rotation 0.000000 0.000000 1.000000 3.141593
                                                                          children [
                                                                            Box {
                                                                               size 0.042000 0.006500 0.037000
                                                                            }
                                                                          ]
                                                                        }
                                                                        physics Physics {
                                                                          density -1
                                                                          mass 0.010000
                                                                          centerOfMass [ 0.000000 0.000000 0.000000 ]
                                                                          inertiaMatrix [
                                                                            1.000000e-02 1.000000e-02 1.000000e-02
                                                                            0.000000e+00 0.000000e+00 0.000000e+00
                                                                          ]
                                                                        }
                                                                      }
                                                                    ]
                                                                    name "l_gripper_l_finger"
                                                                    boundingObject Group {
                                                                      children [
                                                                        Transform {
                                                                          translation 0.000000 0.017250 0.061500
                                                                          rotation 0.000000 0.000000 -1.000000 3.141593
                                                                          children [
                                                                            Box {
                                                                               size 0.010000 0.013500 0.112700
                                                                            }
                                                                          ]
                                                                        }
                                                                        Transform {
                                                                          translation -0.005000 -0.003000 0.008300
                                                                          rotation 0.000000 0.000000 -1.000000 3.141593
                                                                          children [
                                                                            Box {
                                                                               size 0.010000 0.050000 0.017000
                                                                            }
                                                                          ]
                                                                        }
                                                                      ]
                                                                    }
                                                                    physics Physics {
                                                                      density -1
                                                                      mass 0.020000
                                                                      centerOfMass [ 0.000000 0.000000 0.000000 ]
                                                                      inertiaMatrix [
                                                                        1.000000e-02 1.000000e-02 1.000000e-02
                                                                        0.000000e+00 0.000000e+00 0.000000e+00
                                                                      ]
                                                                    }
                                                                  }
                                                                }
                                                                SliderJoint {
                                                                  jointParameters JointParameters {
                                                                    axis 0.000000 1.000000 0.000000
                                                                    dampingConstant 0.7
                                                                  }
                                                                  device [
                                                                    LinearMotor {
                                                                      name "l_gripper_r_finger_joint"
                                                                      maxVelocity 5.0
                                                                      minPosition -0.020833
                                                                      maxForce 20.0
                                                                    }
                                                                    PositionSensor {
                                                                      name "l_gripper_r_finger_joint_sensor"
                                                                    }
                                                                  ]
                                                                  endPoint Solid {
                                                                    translation 0.000000 0.001500 0.020000
                                                                    children [
                                                                      USE extended_narrow_visual
                                                                      Solid {
                                                                        translation 0.000000 -0.017250 0.112700
                                                                        children [
                                                                          USE paddle_tip_visual
                                                                        ]
                                                                        name "l_gripper_r_finger_tip"
                                                                        boundingObject Transform {
                                                                          translation 0.000000 0.004500 -0.015000
                                                                          children [
                                                                            Box {
                                                                               size 0.042000 0.006500 0.037000
                                                                            }
                                                                          ]
                                                                        }
                                                                        physics Physics {
                                                                          density -1
                                                                          mass 0.010000
                                                                          centerOfMass [ 0.000000 0.000000 0.000000 ]
                                                                          inertiaMatrix [
                                                                            1.000000e-02 1.000000e-02 1.000000e-02
                                                                            0.000000e+00 0.000000e+00 0.000000e+00
                                                                          ]
                                                                        }
                                                                      }
                                                                    ]
                                                                    name "l_gripper_r_finger"
                                                                    boundingObject Group {
                                                                      children [
                                                                        Transform {
                                                                          translation 0.000000 -0.017250 0.061500
                                                                          children [
                                                                            Box {
                                                                               size 0.010000 0.013500 0.112700
                                                                            }
                                                                          ]
                                                                        }
                                                                        Transform {
                                                                          translation 0.005000 0.003000 0.008300
                                                                          children [
                                                                            Box {
                                                                               size 0.010000 0.050000 0.017000
                                                                            }
                                                                          ]
                                                                        }
                                                                      ]
                                                                    }
                                                                    physics Physics {
                                                                      density -1
                                                                      mass 0.020000
                                                                      centerOfMass [ 0.000000 0.000000 0.000000 ]
                                                                      inertiaMatrix [
                                                                        1.000000e-02 1.000000e-02 1.000000e-02
                                                                        0.000000e+00 0.000000e+00 0.000000e+00
                                                                      ]
                                                                    }
                                                                  }
                                                                }
                                                              ]
                                                              name "left_gripper_base"
                                                              boundingObject Transform {
                                                                rotation -0.000000 0.707107 0.707107 3.141593
                                                                children [
                                                                  Cylinder {
                                                                    radius 0.029
                                                                    height 0.1
                                                                  }
                                                                ]
                                                              }
                                                              physics Physics {
                                                                density -1
                                                                mass 0.300000
                                                                centerOfMass [ 0.000000 0.000000 0.000000 ]
                                                                inertiaMatrix [
                                                                  2.000000e-08 2.000000e-08 3.000000e-08
                                                                  0.000000e+00 2.536327e-25 2.220446e-24
                                                                ]
                                                              }
                                                            }
                                                          ]
                                                          name "left_hand"
                                                          boundingObject Transform {
                                                            translation 0.000000 0.000000 -0.023200
                                                            children [
                                                              Cylinder {
                                                                radius 0.04
                                                                height 0.0464
                                                              }
                                                            ]
                                                          }
                                                          physics Physics {
                                                            density -1
                                                            mass 0.191250
                                                            centerOfMass [ 0.010930 0.000420 -0.015320 ]
                                                            inertiaMatrix [
                                                              1.758800e-04 2.116638e-04 2.374540e-04
                                                              1.470730e-06 2.436330e-05 1.726890e-06
                                                            ]
                                                          }
                                                        }
                                                      ]
                                                      name "left_wrist"
                                                      boundingObject Cylinder {
                                                        radius 0.06
                                                        height 0.165
                                                      }
                                                      physics Physics {
                                                        density -1
                                                        mass 0.350930
                                                        centerOfMass [ 0.001980 0.001250 0.018550 ]
                                                        inertiaMatrix [
                                                          2.528916e-04 2.688601e-04 3.074118e-04
                                                          5.753110e-06 -1.593450e-06 -5.198180e-06
                                                        ]
                                                      }
                                                    }
                                                  }
                                                ]
                                                name "left_lower_forearm"
                                                boundingObject Cylinder {
                                                  radius 0.06
                                                  height 0.1
                                                }
                                                physics Physics {
                                                  density -1
                                                  mass 1.609790
                                                  centerOfMass [ 0.060410 0.006970 0.006000 ]
                                                  inertiaMatrix [
                                                    3.876072e-03 7.005379e-03 5.527552e-03
                                                    -4.438478e-04 -2.111504e-04 1.534807e-04
                                                  ]
                                                }
                                              }
                                            }
                                          ]
                                          name "left_upper_forearm"
                                          boundingObject Transform {
                                            translation 0.000000 0.000000 -0.044000
                                            children [
                                              Cylinder {
                                                radius 0.06
                                                height 0.088
                                              }
                                            ]
                                          }
                                          physics Physics {
                                            density -1
                                            mass 2.246650
                                            centerOfMass [ -0.001680 0.004600 0.139520 ]
                                            inertiaMatrix [
                                              1.667743e-02 1.675457e-02 3.746312e-03
                                              1.840371e-04 1.865763e-04 -6.473235e-04
                                            ]
                                          }
                                        }
                                      }
                                      Solid {
                                        translation 0.088000 0.000000 0.000000
                                        rotation 0.577350 0.577350 0.577350 2.094395
                                        name "left_upper_forearm_visual"
                                        boundingObject Transform {
                                          translation 0.000000 0.000000 0.136000
                                          children [
                                            Cylinder {
                                              radius 0.06
                                              height 0.272
                                            }
                                          ]
                                        }
                                        physics Physics {
                                          density -1
                                          mass 0.000100
                                          centerOfMass [ 0.000000 0.000000 0.000000 ]
                                          inertiaMatrix [
                                            1.000000e-08 1.000000e-08 1.000000e-08
                                            0.000000e+00 0.000000e+00 0.000000e+00
                                          ]
                                        }
                                      }
                                    ]
                                    name "left_lower_elbow"
                                    boundingObject Cylinder {
                                      radius 0.06
                                      height 0.1
                                    }
                                    physics Physics {
                                      density -1
                                      mass 2.072060
                                      centerOfMass [ 0.026110 0.001590 -0.011170 ]
                                      inertiaMatrix [
                                        7.115827e-03 1.318228e-02 9.268521e-03
                                        3.603617e-04 7.459496e-04 -1.966342e-04
                                      ]
                                    }
                                  }
                                }
                              ]
                              name "left_upper_elbow"
                              boundingObject Transform {
                                translation 0.000000 0.000000 -0.053500
                                children [
                                  Cylinder {
                                    radius 0.06
                                    height 0.107
                                  }
                                ]
                              }
                              physics Physics {
                                density -1
                                mass 4.312720
                                centerOfMass [ -0.002760 0.001320 0.180860 ]
                                inertiaMatrix [
                                  2.661734e-02 2.844355e-02 1.248008e-02
                                  2.927063e-04 3.921899e-03 1.083893e-03
                                ]
                              }
                            }
                          }
                          Solid {
                            translation 0.107000 0.000000 0.000000
                            rotation 0.577350 0.577350 0.577350 2.094395
                            name "left_upper_elbow_visual"
                            boundingObject Transform {
                              translation 0.000000 0.000000 0.136500
                              children [
                                Cylinder {
                                  radius 0.06
                                  height 0.273
                                }
                              ]
                            }
                            physics Physics {
                              density -1
                              mass 0.000100
                              centerOfMass [ 0.000000 0.000000 0.000000 ]
                              inertiaMatrix [
                                1.000000e-08 1.000000e-08 1.000000e-08
                                0.000000e+00 0.000000e+00 0.000000e+00
                              ]
                            }
                          }
                        ]
                        name "left_lower_shoulder"
                        boundingObject Cylinder {
                          radius 0.06
                          height 0.12
                        }
                        physics Physics {
                          density -1
                          mass 3.226980
                          centerOfMass [ 0.068450 0.002690 -0.005290 ]
                          inertiaMatrix [
                            1.175209e-02 2.788598e-02 2.078749e-02
                            -3.009640e-04 2.076758e-03 -1.882199e-04
                          ]
                        }
                      }
                    }
                  ]
                  name "left_upper_shoulder"
                  boundingObject Transform {
                    translation 0.000000 0.000000 0.136100
                    children [
                      Cylinder {
                        radius 0.06
                        height 0.2722
                      }
                    ]
                  }
                  physics Physics {
                    density -1
                    mass 5.700440
                    centerOfMass [ 0.017830 0.000860 0.191270 ]
                    inertiaMatrix [
                      4.709102e-02 3.766976e-02 3.595988e-02
                      1.278756e-04 6.148700e-03 7.808690e-04
                    ]
                  }
                }
              }
            ]
            name "left_arm_mount"
            physics Physics {
              density -1
              mass 0.000100
              centerOfMass [ 0.000000 0.000000 0.000000 ]
              inertiaMatrix [
                1.000000e-08 1.000000e-08 1.000000e-08
                0.000000e+00 0.000000e+00 0.000000e+00
              ]
            }
          }
          Solid {
            children [
              DEF PEDESTAL_visual CadShape {
                url "baxter/meshes/base/PEDESTAL.DAE"
              }
            ]
            name "pedestal"
            boundingObject DEF pedestal_link_collision Mesh {
              url "baxter/meshes/base/pedestal_link_collision.DAE"
            }
            physics Physics {
              density -1
              mass 60.863977
              centerOfMass [ 0.000000 0.000000 0.000000 ]
              inertiaMatrix [
                5.063593e+00 6.086894e+00 4.961919e+00
                1.034170e-03 8.019963e-01 1.053110e-03
              ]
            }
          }
        ]
        name "torso"
        boundingObject DEF base_link_collision Mesh {
          url "baxter/meshes/torso/base_link_collision.DAE"
        }
        physics Physics {
          density -1
          mass 35.336455
          centerOfMass [ 0.000000 0.000000 0.000000 ]
          inertiaMatrix [
            1.849155e+00 1.662671e+00 8.022390e-01
            -3.540000e-04 -1.541880e-01 3.292000e-03
          ]
        }
      }
    ]
    name IS name
  }
}
